<?xml version="1.0" ?>
<sdf version="1.5">
  <model name="clap_vert">
    <link name="clap">
      <self_collide>1</self_collide>
      <inertial>
		<pose>-0.047 -0.015 0.065 0 0 0</pose>
		<mass>0.15</mass>
        <inertia>
            <ixx>0.0002222088631592061</ixx>
            <ixy>0.00009576025452225838</ixy>
            <ixz>0</ixz>
            <iyy>0.00026807677377627993</iyy>
            <iyz>0</iyz>
            <izz>0.00006835231764351083</izz>
        </inertia>
	  </inertial>
	<collision name="collision">
	  <geometry>
	    <mesh>
		<scale>0.001 0.001 0.001</scale>
		<uri>model://clap_jaune/meshes/clap.dae</uri>
	    </mesh>
	  </geometry>
	</collision>
	<visual name="visual">
	  <geometry>
	    <mesh>
		<scale>0.001 0.001 0.001</scale>
		<uri>model://clap_jaune/meshes/clap.dae</uri>
	    </mesh>
	  </geometry>
        <material>
          <script>
            <uri>file://media/materials/scripts/gazebo.material</uri>
            <name>Gazebo/Green</name>
          </script>
        </material>
	</visual>
      </link>
      <joint type="revolute" name="hinge">
	<pose>0 0 0 0 -2.007 0</pose><!-- 2.007 rad = 115 degres-->
	<child>clap</child>
	<parent>world</parent>
	<axis>
	   <xyz>0 1 0</xyz>
	   <limit>
		<upper>2.007</upper>
		<lower>0</lower>
	   </limit>	
	</axis>
	
       </joint>
    </model>
 </sdf>
