<?xml version="1.0" ?>
<sdf version="1.5">
  <model name="clap_vert">
    <link name="clap">
        <self_collide>1</self_collide>
        <inertial>
	  <mass>30.39</mass>
	</inertial>
	<collision name="collision">
	  <geometry>
	    <mesh>
		<scale>0.001 0.001 0.001</scale>
		<uri>file://models/clap_jaune/meshes/clap.dae</uri>
	    </mesh>
	  </geometry>
	</collision>
	<visual name="visual">
	  <geometry>
	    <mesh>
		<scale>0.001 0.001 0.001</scale>
		<uri>file://models/clap_jaune/meshes/clap.dae</uri>
	    </mesh>
	  </geometry>
        <material>
          <script>
            <uri>file://media/materials/scripts/gazebo.material</uri>
            <name>Gazebo/Green</name>
          </script>
        </material>
	</visual>
      </link>
      <joint type="revolute" name="hinge">
	<pose>0 0 0 0 -2.007 0</pose><!-- 2.007 rad = 115 degres-->
	<child>clap</child>
	<parent>world</parent>
	<axis>
	   <xyz>0 1 0</xyz>
	   <limit>
		<upper>0</upper>
		<lower>-2.007</lower>
	   </limit>
	</axis>
	
       </joint>
    </model>
 </sdf>
