<?xml version="1.0" ?>
<sdf version="1.5">
  <model name="clap_vert">
    <link name="clap">
	<pose>0.075 0 0.015 0 0 0</pose>
        <self_collide>1</self_collide>
        <inertial>
	  <mass>.39</mass>
	</inertial>
	<collision name="collision">
	  <geometry>
    		<!--
	    <mesh>
		<scale>0.001 0.001 0.001</scale>
		<uri>file://models/clap_jaune/meshes/clap.dae</uri>
	    </mesh>
		-->
		<box>
		  <size>0.15 0.03 0.03</size>
		</box>
		
	  </geometry>
	</collision>
	<visual name="visual">
	  <geometry>
    		<!--
	    <mesh>
		<scale>0.001 0.001 0.001</scale>
		<uri>file://models/clap_jaune/meshes/clap.dae</uri>
	    </mesh>
		-->		
		<box>
		  <size>0.15 0.03 0.03</size>
		</box>

	  </geometry>
        <material>
          <script>
            <uri>file://media/materials/scripts/gazebo.material</uri>
            <name>Gazebo/Green</name>
          </script>
        </material>
	</visual>
      </link>
      <joint type="revolute" name="hinge">
	<pose>-0.075 0 -.015 0 0 0</pose>
	<child>clap</child>
	<parent>world</parent>
	<axis>
	   <xyz>0 1 0</xyz>
	</axis>
       </joint>
    </model>
 </sdf>
